Workbook

Sheet Resumen
A1: Puntos de venta por zona — mapa «la plata zonas»
A2: Fuente: Google My Maps «la plata zonas». Zona asignada según en qué polígono cae el pin del mapa.
A4: Zona | B4: Puntos de venta | C4: A revisar
A5: Zona 01 - Villa Elisa | B5: =COUNTIF(Todos!$A$5:$A$553,A5) -> 24 | C5: =COUNTIFS(Todos!$A$5:$A$553,A5,Todos!$H$5:$H$553,"<>OK") -> 0
A6: Zona 02 - City Bell | B6: =COUNTIF(Todos!$A$5:$A$553,A6) -> 26 | C6: =COUNTIFS(Todos!$A$5:$A$553,A6,Todos!$H$5:$H$553,"<>OK") -> 0
A7: Zona 03 - Gonnet Ringuelet | B7: =COUNTIF(Todos!$A$5:$A$553,A7) -> 22 | C7: =COUNTIFS(Todos!$A$5:$A$553,A7,Todos!$H$5:$H$553,"<>OK") -> 0
A8: Zona 04 - Tolosa | B8: =COUNTIF(Todos!$A$5:$A$553,A8) -> 27 | C8: =COUNTIFS(Todos!$A$5:$A$553,A8,Todos!$H$5:$H$553,"<>OK") -> 0
A9: Zona 05 - Lateral San Carlos | B9: =COUNTIF(Todos!$A$5:$A$553,A9) -> 22 | C9: =COUNTIFS(Todos!$A$5:$A$553,A9,Todos!$H$5:$H$553,"<>OK") -> 0
A10: Zona 06 - Hipodromo | B10: =COUNTIF(Todos!$A$5:$A$553,A10) -> 25 | C10: =COUNTIFS(Todos!$A$5:$A$553,A10,Todos!$H$5:$H$553,"<>OK") -> 0
A11: Zona 07 - Lateral Norte | B11: =COUNTIF(Todos!$A$5:$A$553,A11) -> 32 | C11: =COUNTIFS(Todos!$A$5:$A$553,A11,Todos!$H$5:$H$553,"<>OK") -> 0
A12: Zona 08 - Lateral Centro Norte | B12: =COUNTIF(Todos!$A$5:$A$553,A12) -> 25 | C12: =COUNTIFS(Todos!$A$5:$A$553,A12,Todos!$H$5:$H$553,"<>OK") -> 0
A13: Zona 10 - Noroeste | B13: =COUNTIF(Todos!$A$5:$A$553,A13) -> 23 | C13: =COUNTIFS(Todos!$A$5:$A$553,A13,Todos!$H$5:$H$553,"<>OK") -> 0
A14: Zona 11 - Centro | B14: =COUNTIF(Todos!$A$5:$A$553,A14) -> 30 | C14: =COUNTIFS(Todos!$A$5:$A$553,A14,Todos!$H$5:$H$553,"<>OK") -> 0
A15: Zona 12 - Centro 2 | B15: =COUNTIF(Todos!$A$5:$A$553,A15) -> 33 | C15: =COUNTIFS(Todos!$A$5:$A$553,A15,Todos!$H$5:$H$553,"<>OK") -> 0
A16: Zona 13 - Lateral Sureste | B16: =COUNTIF(Todos!$A$5:$A$553,A16) -> 35 | C16: =COUNTIFS(Todos!$A$5:$A$553,A16,Todos!$H$5:$H$553,"<>OK") -> 0
... A23: Sin zona | B23: =COUNTIF(Todos!$A$5:$A$553,A23) -> 43 | C23: =COUNTIFS(Todos!$A$5:$A$553,A23,Todos!$H$5:$H$553,"<>OK") -> 43
A24: Total | B24: =SUM(B5:B23) -> 549 | C24: =SUM(C5:C23) -> 43
A26: Notas:
A27: • Zonas tomadas del mapa «la plata zonas» actualizado: 18 zonas dibujadas (no hay zona 9 ni zona 14).
A28: • Los puntos fuera de las zonas dibujadas (Gorina, Punta Lara, Sicardi, parte de Villa Elvira y bordes) figuran en «Sin zona», con la zona más cercana como referencia.
A29: • 43 pines que Google había ubicado mal fueron corregidos con la grilla de calles de La Plata (en verde, detalle en «Corrección aplicada»).

Sheet Todos
A1: Puntos de venta por zona — Gran La Plata
A2: 549 puntos de venta
A4: Zona | B4: Punto de venta | C4: Dirección (mapa) | D4: Dirección original | E4: Barrio | F4: Localidad | G4: Observación | H4: Estado | I4: Zona más cercana (si está fuera) | J4: Lat | K4: Lng | L4: Ver en Maps | M4: Corrección aplicada
A5: Zona 01 - Villa Elisa | B5: CHEN JUN | C5: Calle 446 y Calle 28BIS, City Bell, Buenos Aires, Argentina | D5: 446 ESQ 28BIS | E5: City Bell | F5: City Bell | H5: OK | J5: -34.880346 | K5: -58.084531 | L5: Abrir
A6: Zona 01 - Villa Elisa | B6: KIOSCO AYTINA | C6: Belgrano y Calle 451, City Bell, Buenos Aires, Argentina | D6: BELGRANO Y 451 | E6: City Bell | F6: City Bell | H6: OK | J6: -34.876267 | K6: -58.076594 | L6: Abrir
A7: Zona 01 - Villa Elisa | B7: PATRICIA TOLOSA MAXIKIOSCO MAR | C7: Calle 450 y Camino General Belgrano, City Bell, Buenos Aires, Argentina | D7: CALLE 450 CASI CNO. GRAL BELGRANO | E7: City Bell | F7: City Bell | H7: OK | J7: -34.875981 | K7: -58.077777 | L7: Abrir
A8: Zona 01 - Villa Elisa | B8: RAQUEL ALMACEN MANU | C8: Calle 21D y Calle 454, City Bell, Buenos Aires, Argentina | D8: 21D E/ 454 Y 455 | E8: City Bell | F8: City Bell | H8: OK | J8: -34.875057 | K8: -58.072214 | L8: Abrir
A9: Zona 01 - Villa Elisa | B9: ALE BODEGA EL REY | C9: Cno. Centenario 964, Villa Elisa, Buenos Aires, Argentina | D9: CNO. CENTENARIO º964 E/ ARANA Y 43 | E9: Villa Elisa | F9: Villa Elisa | H9: OK | J9: -34.853605 | K9: -58.079529 | L9: Abrir
A10: Zona 01 - Villa Elisa | B10: ALMACEN DON JOSE (ROBERTO) | C10: Calle 421BIS 555, Villa Elisa, Buenos Aires, Argentina | D10: 421BIS E/ 6 BIS Y 7 Nº555 | E10: Villa Elisa | F10: Villa Elisa | H10: OK | J10: -34.855737 | K10: -58.077369 | L10: Abrir
A11: Zona 01 - Villa Elisa | B11: ANDRÉS CONTI (SOLONESKI) | C11: Calle 419 2744, Villa Elisa, Buenos Aires, Argentina | D11: 419 N 2744 E/28 Y 28BIS | E11: Villa Elisa | F11: Villa Elisa | H11: OK | J11: -34.873158 | K11: -58.101882 | L11: Abrir
A12: Zona 01 - Villa Elisa | B12: AUDA CHAMORRO | C12: Calle 30BIS 3929, Villa Elisa, Buenos Aires, Argentina | D12: 30 BIS N°3929 E/ 429 Y 430 | E12: Villa Elisa | F12: Villa Elisa | H12: OK | J12: -34.880668 | K12: -58.094163 | L12: Abrir
A13: Zona 01 - Villa Elisa | B13: CAPORNIO CLAUDIO | C13: Cno. Centenario 795, Villa Elisa, Buenos Aires, Argentina | D13: CNO. CENTENARIO Y DIAG 4 Nº795 | E13: Villa Elisa | F13: Villa Elisa | H13: OK | J13: -34.853681 | K13: -58.077859 | L13: Abrir
A14: Zona 01 - Villa Elisa | B14: CARLA AGUERO NUEVA DIRECCIÓN | C14: Calle 404 y Calle 115BIS, Villa Elisa, Buenos Aires, Argentina | D14: 404 E/ 115 BIS Y 117 (SIN NÚMERO) | E14: Villa Elisa | F14: Villa Elisa | H14: OK | J14: -34.841036 | K14: -58.089261 | L14: Abrir
A15: Zona 01 - Villa Elisa | B15: COELHO RUBEN | C15: Calle 3 890, Villa Elisa, Buenos Aires, Argentina | D15: 3 N 890 | E15: Villa Elisa | F15: Villa Elisa | H15: OK | J15: -34.850968 | K15: -58.075887 | L15: Abrir
A16: Zona 01 - Villa Elisa | B16: EZEQUIEL CALFA SUPER MESSI | C16: Calle 3 744, Villa Elisa, Buenos Aires, Argentina | D16: CALLE 3 744 E/ 419 Y 421 | E16: Villa Elisa Las Torres | F16: Villa Elisa | H16: OK | J16: -34.851378 | K16: -58.075397 | L16: Abrir
... A135: Zona 06 - Hipodromo | B135: DISTRI RAICES - COOP. SAN PEDRO | C135: Calle 32 286, La Plata, Buenos Aires, Argentina | D135: 32 E/ 1 Y 115 N286 | E135: La Plata | F135: La Plata | H135: OK | J135: -34.894823 | K135: -57.962316 | L135: Abrir
A136: Zona 06 - Hipodromo | B136: ENRIQUE GUILLERMO JONGEWAARD | C136: Diag.80 254, La Plata, Buenos Aires, Argentina | D136: DIAG.80 N°254 E 117Y118 | F136: La Plata | H136: OK | J136: -34.898861 | K136: -57.949319 | L136: Abrir
A137: Zona 06 - Hipodromo | B137: ESTEFANIA ROJAS | C137: Diagonal 80 465, La Plata, Buenos Aires, Argentina | D137: DIAG 80 Nº 465 E/ 115 Y 116 | E137: La Plata | F137: La Plata | H137: OK | J137: -34.902589 | K137: -57.949475 | L137: Abrir
A138: Zona 06 - Hipodromo | B138: GISELA SOLEDAD LLANOS | C138: Calle 37 182, La Plata, Buenos Aires, Argentina | D138: CALLE 37 N182 E/ 116 Y 117 FRENTE A HOSPITAL ROSSI | E138: La Plata | F138: La Plata | H138: OK | J138: -34.896952 | K138: -57.954609 | L138: Abrir
A139: Zona 06 - Hipodromo | B139: HORACIO STREMEL | C139: Calle 1 599, La Plata, Buenos Aires, Argentina | D139: 1 Y 44 º599 | E139: La Plata | F139: La Plata | H139: OK | J139: -34.904347 | K139: -57.950111 | L139: Abrir | M139: Pin corregido según la grilla de calles de La Plata
A140: Zona 06 - Hipodromo | B140: LLAMAR ANTES - LUCIANO DIANA (KIOSCO PARADA 1) | C140: Avenida 1 631, La Plata, Buenos Aires, Argentina | D140: AV 1 N°631 e/ 44 Y 45 | E140: La Plata | F140: La Plata | H140: OK | J140: -34.905708 | K140: -57.948597 | L140: Abrir
A141: Zona 06 - Hipodromo | B141: MARIANA ESCRICH | C141: Calle 39 y Diagonal 114, La Plata, Buenos Aires, Argentina | D141: 39 Y DIAG 114 | E141: La Plata | F141: La Plata | H141: OK | J141: -34.89564 | K141: -57.948038 | L141: Abrir
A142: Zona 06 - Hipodromo | B142: MARTIN ARREGUI (RELOJES ARREGUI) | C142: Calle 1 575, La Plata, Buenos Aires, Argentina | D142: 1 Nº 575 E/ 43 Y 44 | E142: La Plata | F142: La Plata | H142: OK | J142: -34.903985 | K142: -57.950598 | L142: Abrir | M142: Pin corregido según la grilla de calles de La Plata
A143: Zona 06 - Hipodromo | B143: MAURO GONZALEZ | C143: Calle 2 631, La Plata, Buenos Aires, Argentina | D143: 2 N°631 E/ 44 Y 45 | E143: La Plata | F143: La Plata | H143: OK | J143: -34.906749 | K143: -57.949675 | L143: Abrir | M143: Caía en el solape zonas 5/17: asignado a 17 (Melchor Romero)
A144: Zona 06 - Hipodromo | B144: REAL IMPERIO LA REINA | C144: Avenida 1 604, La Plata, Buenos Aires, Argentina | D144: AV 1 604 ESQ 44 | E144: La Plata | F144: La Plata | H144: OK | J144: -34.905052 | K144: -57.948801 | L144: Abrir
A145: Zona 06 - Hipodromo | B145: ROXANA LUJAN | C145: Calle 38 35, La Plata, Buenos Aires, Argentina | D145: 38 Nº35 E/ 120 Y 121 | E145: La Plata | F145: La Plata | H145: OK | J145: -34.894947 | K145: -57.950653 | L145: Abrir
A146: Zona 06 - Hipodromo | B146: SANZ JAVIER | C146: Calle 36 228, La Plata, Buenos Aires, Argentina | D146: 36 Y DIAGONAL 74 º228 - SHELL | E146: La Plata | F146: La Plata | H146: OK | J146: -34.89701 | K146: -57.956647 | L146: Abrir
A147: Zona 06 - Hipodromo | B147: SARA VANESSA CARBAJAL | C147: Calle 40 87, La Plata, Buenos Aires, Argentina | D147: calle 40 E 118 Y 119 n87 | E147: La Plata | F147: La Plata | H147: OK | J147: -34.894967 | K147: -57.945959 | L147: Abrir
A148: Zona 06 - Hipodromo | B148: SILVIA PORCO | C148: Calle 42 308, La Plata, Buenos Aires, Argentina | D148: 42 Nº308 E/ 1 Y 2 | E148: La Plata | F148: La Plata | H148: OK | J148: -34.903708 | K148: -57.951488 | L148: Abrir
A149: Zona 06 - Hipodromo | B149: SOLEDAD CISNEROS | C149: Calle 2 y Calle 45, La Plata, Buenos Aires, Argentina | D149: CALLE 2 E/ 45 Y 46 | E149: La Plata | F149: La Plata | H149: OK | J149: -34.906071 | K149: -57.949848 | L149: Abrir
A150: Zona 06 - Hipodromo | B150: VIVIANA ERRAMOUSPE | C150: Calle 40 92, La Plata, Buenos Aires, Argentina | D150: 40 º92 DIAG 80 | E150: La Plata | F150: La Plata | H150: OK | J150: -34.894742 | K150: -57.946328 | L150: Abrir
A151: Zona 07 - Lateral Norte | B151: ADRIANA LORENA LEDESMA LO DE ADRY | C151: Calle 31 2332, José Hernández, La Plata, Buenos Aires, Argentina | D151: 31 E/ 508 Y 509 º2332 | E151: José Hernández | F151: José Hernández, La Plata | H151: OK | J151: -34.917095 | K151: -57.969263 | L151: Abrir
A152: Zona 07 - Lateral Norte | B152: MATIAS RAMOS | C152: Calle 133 2281, José Hernández, La Plata, Buenos Aires, Argentina | D152: 133 º2281 E/ 509 Y 510 | E152: José Hernández | F152: José Hernández, La Plata | H152: OK | J152: -34.917095 | K152: -57.969263 | L152: Abrir
A153: Zona 07 - Lateral Norte | B153: BONTEMPO RAMIRO | C153: Plaza Paso 51, La Plata, Buenos Aires, Argentina | D153: PLAZA PASO N 51 ESQ. 13 Y 44 | E153: La Plata | F153: La Plata | H153: OK | J153: -34.916988 | K153: -57.961736 | L153: Abrir
A154: Zona 07 - Lateral Norte | B154: DAMIAN ZLATAR - KIOSCO RUMBO | C154: Calle 12 649, La Plata, Buenos Aires, Argentina | D154: CALLE 12 N649 ESQ 45 | E154: La Plata | F154: La Plata | H154: OK | J154: -34.916202 | K154: -57.959436 | L154: Abrir
A155: Zona 07 - Lateral Norte | B155: FEDERICO KOLENDER | C155: Calle 12 805, La Plata, Buenos Aires, Argentina | D155: 12 805 E/ 48 Y 49 | E155: La Plata | F155: La Plata | H155: OK | J155: -34.91861 | K155: -57.956301 | L155: Abrir
... A160: Zona 07 - Lateral Norte | B160: GRISELLA VILLIVA | C160: Calle 42 1147, La Plata, Buenos Aires, Argentina | D160: 42 º1147 ESQ 18 | E160: La Plata 3 | F160: La Plata | H160: OK | J160: -34.919103 | K160: -57.968863 | L160: Abrir
A161: Zona 07 - Lateral Norte | B161: HORACIO TILBE (JUAN) LP | C161: Calle 44 799, La Plata, Buenos Aires, Argentina | D161: 44 N 799 Y 11 | E161: La Plata | F161: La Plata | H161: OK | J161: -34.913887 | K161: -57.960192 | L161: Abrir | M161: Pin corregido según la grilla de calles de La Plata
A162: Zona 07 - Lateral Norte | B162: JUAN PABLO BISOGNI | C162: Calle 15 1004, La Plata, Buenos Aires, Argentina | D162: CALLE 15 1004 ESQ 44 | E162: La Plata | F162: La Plata | H162: OK | J162: -34.917703 | K162: -57.964224 | L162: Abrir | M162: Pin corregido según la grilla de calles de La Plata
A163: Zona 07 - Lateral Norte | B163: KAPRI ALONZO LUIS PLAZA N°41 | C163: Plaza Paso 41, La Plata, Buenos Aires, Argentina | D163: PLAZA PASO N 41 | E163: La Plata | F163: La Plata | H163: OK | J163: -34.915727 | K163: -57.961885 | L163: Abrir
...

Sheet Zona 01 Villa Elisa
A1: Zona 01 - Villa Elisa | B1: CHRISTIAN
A2: 24 puntos de venta
A4: Zona | B4: Punto de venta | C4: Dirección (mapa) | D4: Dirección original | E4: Barrio | F4: Localidad | G4: Observación | H4: Estado | I4: Zona más cercana (si está fuera) | J4: Lat | K4: Lng | L4: Ver en Maps | M4: Corrección aplicada
A5: Zona 01 - Villa Elisa | B5: CHEN JUN | C5: Calle 446 y Calle 28BIS, City Bell, Buenos Aires, Argentina | D5: 446 ESQ 28BIS | E5: City Bell | F5: City Bell | H5: OK | J5: -34.880346 | K5: -58.084531 | L5: Abrir
A6: Zona 01 - Villa Elisa | B6: KIOSCO AYTINA | C6: Belgrano y Calle 451, City Bell, Buenos Aires, Argentina | D6: BELGRANO Y 451 | E6: City Bell | F6: City Bell | H6: OK | J6: -34.876267 | K6: -58.076594 | L6: Abrir
A7: Zona 01 - Villa Elisa | B7: PATRICIA TOLOSA MAXIKIOSCO MAR | C7: Calle 450 y Camino General Belgrano, City Bell, Buenos Aires, Argentina | D7: CALLE 450 CASI CNO. GRAL BELGRANO | E7: City Bell | F7: City Bell | H7: OK | J7: -34.875981 | K7: -58.077777 | L7: Abrir
A8: Zona 01 - Villa Elisa | B8: RAQUEL ALMACEN MANU | C8: Calle 21D y Calle 454, City Bell, Buenos Aires, Argentina | D8: 21D E/ 454 Y 455 | E8: City Bell | F8: City Bell | H8: OK | J8: -34.875057 | K8: -58.072214 | L8: Abrir
A9: Zona 01 - Villa Elisa | B9: ALE BODEGA EL REY | C9: Cno. Centenario 964, Villa Elisa, Buenos Aires, Argentina | D9: CNO. CENTENARIO º964 E/ ARANA Y 43 | E9: Villa Elisa | F9: Villa Elisa | H9: OK | J9: -34.853605 | K9: -58.079529 | L9: Abrir
A10: Zona 01 - Villa Elisa | B10: ALMACEN DON JOSE (ROBERTO) | C10: Calle 421BIS 555, Villa Elisa, Buenos Aires, Argentina | D10: 421BIS E/ 6 BIS Y 7 Nº555 | E10: Villa Elisa | F10: Villa Elisa | H10: OK | J10: -34.855737 | K10: -58.077369 | L10: Abrir
A11: Zona 01 - Villa Elisa | B11: ANDRÉS CONTI (SOLONESKI) | C11: Calle 419 2744, Villa Elisa, Buenos Aires, Argentina | D11: 419 N 2744 E/28 Y 28BIS | E11: Villa Elisa | F11: Villa Elisa | H11: OK | J11: -34.873158 | K11: -58.101882 | L11: Abrir
A12: Zona 01 - Villa Elisa | B12: AUDA CHAMORRO | C12: Calle 30BIS 3929, Villa Elisa, Buenos Aires, Argentina | D12: 30 BIS N°3929 E/ 429 Y 430 | E12: Villa Elisa | F12: Villa Elisa | H12: OK | J12: -34.880668 | K12: -58.094163 | L12: Abrir
A13: Zona 01 - Villa Elisa | B13: CAPORNIO CLAUDIO | C13: Cno. Centenario 795, Villa Elisa, Buenos Aires, Argentina | D13: CNO. CENTENARIO Y DIAG 4 Nº795 | E13: Villa Elisa | F13: Villa Elisa | H13: OK | J13: -34.853681 | K13: -58.077859 | L13: Abrir
A14: Zona 01 - Villa Elisa | B14: CARLA AGUERO NUEVA DIRECCIÓN | C14: Calle 404 y Calle 115BIS, Villa Elisa, Buenos Aires, Argentina | D14: 404 E/ 115 BIS Y 117 (SIN NÚMERO) | E14: Villa Elisa | F14: Villa Elisa | H14: OK | J14: -34.841036 | K14: -58.089261 | L14: Abrir
A15: Zona 01 - Villa Elisa | B15: COELHO RUBEN | C15: Calle 3 890, Villa Elisa, Buenos Aires, Argentina | D15: 3 N 890 | E15: Villa Elisa | F15: Villa Elisa | H15: OK | J15: -34.850968 | K15: -58.075887 | L15: Abrir
A16: Zona 01 - Villa Elisa | B16: EZEQUIEL CALFA SUPER MESSI | C16: Calle 3 744, Villa Elisa, Buenos Aires, Argentina | D16: CALLE 3 744 E/ 419 Y 421 | E16: Villa Elisa Las Torres | F16: Villa Elisa | H16: OK | J16: -34.851378 | K16: -58.075397 | L16: Abrir
... A28: Zona 01 - Villa Elisa | B28: ZONA NORTE | C28: Calle 419 y Calle 21B, Villa Elisa, Buenos Aires, Argentina | D28: 419 ESQ 21B 1788 | E28: Villa Elisa | F28: Villa Elisa | H28: OK | J28: -34.875489 | K28: -58.104986 | L28: Abrir

Sheet Zona 02 City Bell
A1: Zona 02 - City Bell | B1: CHRISTIAN
A2: 26 puntos de venta
A4: Zona | B4: Punto de venta | C4: Dirección (mapa) | D4: Dirección original | E4: Barrio | F4: Localidad | G4: Observación | H4: Estado | I4: Zona más cercana (si está fuera) | J4: Lat | K4: Lng | L4: Ver en Maps | M4: Corrección aplicada
A5: Zona 02 - City Bell | B5: ALEJANDRO MAXIKIOSCO PUNTO ROJO | C5: Cno Gral Belgrano 595, City Bell, Buenos Aires, Argentina | D5: CNO GRAL BELGRANO º595 ESQ 467 | E5: City Bell | F5: City Bell | H5: OK | J5: -34.880727 | K5: -58.056992 | L5: Abrir
A6: Zona 02 - City Bell | B6: ANGELA ROCIO ZALAZAR | C6: Camino Gral Belgrano 18, City Bell, Buenos Aires, Argentina | D6: CAMINO GRAL BELGRANO N°18 | E6: City Bell | F6: City Bell | H6: OK | J6: -34.882665 | K6: -58.049204 | L6: Abrir
A7: Zona 02 - City Bell | B7: AXION CITY BELL CENTENARIO | C7: Cno Centenario y Calle 466, City Bell, Buenos Aires, Argentina | D7: CNO CENTENARIO Y 466 | E7: City Bell | F7: City Bell | H7: OK | J7: -34.863865 | K7: -58.046577 | L7: Abrir
A8: Zona 02 - City Bell | B8: BODEGON FENIX CITY BELL | C8: Centenario 1032, City Bell, Buenos Aires, Argentina | D8: CENTENARIO Y 461F N1032 (LOCAL VERDE) | E8: City Bell | F8: City Bell | H8: OK | J8: -34.863331 | K8: -58.052511 | L8: Abrir
A9: Zona 02 - City Bell | B9: CANO PABLO | C9: Plaza Belgrano 43, City Bell, Buenos Aires, Argentina | D9: PLAZA BELGRANO N 43 | E9: City Bell | F9: City Bell | H9: OK | J9: -34.871015 | K9: -58.046831 | L9: Abrir
A10: Zona 02 - City Bell | B10: DANIELA SOSA | C10: Calle 467 555, City Bell, Buenos Aires, Argentina | D10: 467 º555 E/ 14 Y 14B | E10: City Bell | F10: City Bell | H10: OK | J10: -34.869401 | K10: -58.049359 | L10: Abrir
A11: Zona 02 - City Bell | B11: DIEGO ALVARO RAMIREZ | C11: Cantilo 16, City Bell, Buenos Aires, Argentina | D11: CANTILO Nº16 ESQ. CENTENARIO | E11: City Bell | F11: City Bell | H11: OK | J11: -34.866615 | K11: -58.042464 | L11: Abrir
A12: Zona 02 - City Bell | B12: EPSTEIN (476 - EL ALM DE GUEMES) | C12: Calle 476 1301, City Bell, Buenos Aires, Argentina | D12: 476 Nº1301 ESQ 19 (ENTRE CNO GRAL BELGRANO Y CENTENARAILOE)JANDRO | E12: City Bell | F12: City Bell | H12: OK | J12: -34.879751 | K12: -58.046662 | L12: Abrir
A13: Zona 02 - City Bell | B13: FERNANDO - LA HORMIGA | C13: Calle 462 y Calle 16, City Bell, Buenos Aires, Argentina | D13: 462 E 16 Y 17 | E13: City Bell | F13: City Bell | H13: OK | J13: -34.870994 | K13: -58.057218 | L13: Abrir
A14: Zona 02 - City Bell | B14: FULL MIX CANTILO Y 14A | C14: Cantilo y Calle 14A, City Bell, Buenos Aires, Argentina | D14: CANTILO Y 14A | E14: City Bell | F14: City Bell | H14: OK | J14: -34.870602 | K14: -58.045579 | L14: Abrir
A15: Zona 02 - City Bell | B15: FULL MIX CANTILO Y CENTENARIO | C15: Cantilo y Centenario, City Bell, Buenos Aires, Argentina | D15: CANTILO Y CENTENARIO | E15: City Bell | F15: City Bell | H15: OK | J15: -34.866094 | K15: -58.042394 | L15: Abrir
A16: Zona 02 - City Bell | B16: GERARDO FIGUEROA HARO | C16: Calle 475 y Calle 10, City Bell, Buenos Aires, Argentina | D16: 475 ESQ 10 | E16: City Bell | F16: City Bell | H16: OK | J16: -34.863786 | K16: -58.037734 | L16: Abrir
... A30: Zona 02 - City Bell | B30: WANG JIANHONG (EX CHEN WENBING MINKAI) | C30: Calle 473 y Calle 15, City Bell, Buenos Aires, Argentina | D30: CALLE 473 E/ 15 Y 15A | E30: City Bell | F30: City Bell | H30: OK | J30: -34.873285 | K30: -58.047507 | L30: Abrir

Sheet Zona 03 Gonnet Ringuelet
A1: Zona 03 - Gonnet Ringuelet | B1: CHRISTIAN
A2: 22 puntos de venta
A4: Zona | B4: Punto de venta | C4: Dirección (mapa) | D4: Dirección original | E4: Barrio | F4: Localidad | G4: Observación | H4: Estado | I4: Zona más cercana (si está fuera) | J4: Lat | K4: Lng | L4: Ver en Maps | M4: Corrección aplicada
A5: Zona 03 - Gonnet Ringuelet | B5: PATRICIA ARIAS GALA | C5: Calle 487 2347, City Bell, Buenos Aires, Argentina | D5: 487 n2347 e/18 Y 19 | E5: City Bell | F5: City Bell | H5: OK | J5: -34.881616 | K5: -58.034093 | L5: Abrir
A6: Zona 03 - Gonnet Ringuelet | B6: ALEJANDRO EPSTEIN (LA POSTA) | C6: Calle 497 1633, Manuel B. Gonnet, Buenos Aires, Argentina | D6: 497 Nº1633 E/ 11 Y 12 | E6: Gonnet | F6: Manuel B. Gonnet | H6: OK | J6: -34.876498 | K6: -58.012923 | L6: Abrir
A7: Zona 03 - Gonnet Ringuelet | B7: CESPEDES MIA AYLEN (ANA) | C7: Calle 508 2389, Manuel B. Gonnet, Buenos Aires, Argentina | D7: 508 E/ 18 Y 19 º2389 | E7: Gonnet | F7: Manuel B. Gonnet | H7: OK | J7: -34.891258 | K7: -58.008404 | L7: Abrir
A8: Zona 03 - Gonnet Ringuelet | B8: CHEN CHEN | C8: Avenida 25 2877, Manuel B. Gonnet, Buenos Aires, Argentina | D8: AV 25 2877 E/ 504 Y 503 | E8: Gonnet | F8: Manuel B. Gonnet | H8: OK | J8: -34.893154 | K8: -58.01976 | L8: Abrir
A9: Zona 03 - Gonnet Ringuelet | B9: CLAUDIO CORNO | C9: Calle 11 3653, Manuel B. Gonnet, Buenos Aires, Argentina | D9: 11 N 3653 E/498 Y 499 | E9: Gonnet 2 | F9: Manuel B. Gonnet | H9: OK | J9: -34.876766 | K9: -58.01093 | L9: Abrir
A10: Zona 03 - Gonnet Ringuelet | B10: FLORENCIA CRUZ - KIOSCO DE AME | C10: Calle 489 2245, Manuel B. Gonnet, Buenos Aires, Argentina | D10: 489 E/ 16BIS Y 17 N 2245 | E10: Gonnet | F10: Manuel B. Gonnet | H10: OK | J10: -34.880449 | K10: -58.031255 | L10: Abrir
A11: Zona 03 - Gonnet Ringuelet | B11: GABRIELA PEREZ KIOSCO GABY GONNET | C11: Calle 25 y Calle 505, Manuel B. Gonnet, Buenos Aires, Argentina | D11: 25 E/ 505 Y 506 | E11: Gonnet | F11: Manuel B. Gonnet | H11: OK | J11: -34.891245 | K11: -58.013801 | L11: Abrir
A12: Zona 03 - Gonnet Ringuelet | B12: HECTOR MATIAS GIL | C12: Calle 23 4320, Manuel B. Gonnet, Buenos Aires, Argentina | D12: 23 E/ 488 Y 489 º4320 | E12: Gonnet | F12: Manuel B. Gonnet | H12: OK | J12: -34.887291 | K12: -58.033714 | L12: Abrir
A13: Zona 03 - Gonnet Ringuelet | B13: JUAN ALBERTO MARTIN | C13: Calle 495 2051, Manuel B. Gonnet, Buenos Aires, Argentina | D13: 495 Y 15BIS º2051 | E13: Gonnet | F13: Manuel B. Gonnet | H13: OK | J13: -34.880178 | K13: -58.022895 | L13: Abrir
A14: Zona 03 - Gonnet Ringuelet | B14: PUNTO ROJO 25 | C14: Calle 25 3044, Manuel B. Gonnet, Buenos Aires, Argentina | D14: 25 º3044 ESQ 501 | E14: Gonnet | F14: Manuel B. Gonnet | H14: OK | J14: -34.892679 | K14: -58.021192 | L14: Abrir
A15: Zona 03 - Gonnet Ringuelet | B15: SUPER 7 LEE EXPRESS | C15: Calle 7 2771, Manuel B. Gonnet, Buenos Aires, Argentina | D15: 7 N 2771 E/ 504 Y 505 | E15: Gonnet | F15: Manuel B. Gonnet | H15: OK | J15: -34.877058 | K15: -58.00019 | L15: Abrir
A16: Zona 03 - Gonnet Ringuelet | B16: VIDELA LIDIA LO DE PELU | C16: Calle 508 101, Manuel B. Gonnet, Buenos Aires, Argentina | D16: 508 N 101 E/ 7 Y 8 | E16: Gonnet | F16: Manuel B. Gonnet | H16: OK | J16: -34.881555 | K16: -57.995897 | L16: Abrir
... A26: Zona 03 - Gonnet Ringuelet | B26: TOMAS LA FRAZIA | C26: Calle 511 1731, Ringuelet, Buenos Aires, Argentina | D26: 511 Nº1731 E/ 12 Y 13 | E26: Ringuelet | F26: Ringuelet | H26: OK | J26: -34.887712 | K26: -57.998426 | L26: Abrir

Sheet Zona 04 Tolosa
A1: Zona 04 - Tolosa | B1: CHRISTIAN
A2: 27 puntos de venta
A4: Zona | B4: Punto de venta | C4: Dirección (mapa) | D4: Dirección original | E4: Barrio | F4: Localidad | G4: Observación | H4: Estado | I4: Zona más cercana (si está fuera) | J4: Lat | K4: Lng | L4: Ver en Maps | M4: Corrección aplicada
A5: Zona 04 - Tolosa | B5: CRISTIAN DOMINGUEZ | C5: Calle 7 47, La Plata, Buenos Aires, Argentina | D5: 7 ENTRE 32 Y 33 N 47 | E5: La Plata | F5: La Plata | H5: OK | J5: -34.899841 | K5: -57.969549 | L5: Abrir
A6: Zona 04 - Tolosa | B6: CLAUDIA INES MARIÑO | C6: Calle 519 1221, Ringuelet, Buenos Aires, Argentina | D6: 519 Nº1221 E/ 7 Y 8 | E6: Ringuelet | F6: Ringuelet | H6: OK | J6: -34.889695 | K6: -57.984181 | L6: Abrir
A7: Zona 04 - Tolosa | B7: FRANCO GUARIE AMADEO NUEVA DIRECCIÓN | C7: Calle 520 1543, Ringuelet, Buenos Aires, Argentina | D7: 520 E/ 10 Y 11 º1543 | E7: Ringuelet | F7: Ringuelet | H7: OK | J7: -34.893467 | K7: -57.986241 | L7: Abrir
A8: Zona 04 - Tolosa | B8: LUISINA ROSSI | C8: Calle 518 938, Ringuelet, Buenos Aires, Argentina | D8: 518 N938 E/ 4 Y 4BIS | E8: Ringuelet | F8: Ringuelet | H8: OK | J8: -34.886563 | K8: -57.982222 | L8: Abrir
A9: Zona 04 - Tolosa | B9: AGUSTINA CAMAÑO | C9: Calle 520 1237, Tolosa, Buenos Aires, Argentina | D9: CALLE 520 E/ 7 Y 8 Nº1237 | E9: Tolosa | F9: Tolosa | H9: OK | J9: -34.890608 | K9: -57.983046 | L9: Abrir
A10: Zona 04 - Tolosa | B10: ALAN SOLARI | C10: Calle 7 1185, Tolosa, Buenos Aires, Argentina | D10: 7 Y 520 Nº 1185 | E10: Tolosa | F10: Tolosa | H10: OK | J10: -34.890406 | K10: -57.982214 | L10: Abrir
A11: Zona 04 - Tolosa | B11: ALEJANDRO MESCHINI | C11: Calle 7 177, Tolosa, Buenos Aires, Argentina | D11: 7 177 E/ 530 Y 531 | E11: Tolosa | F11: Tolosa | H11: OK | J11: -34.898831 | K11: -57.970667 | L11: Abrir
A12: Zona 04 - Tolosa | B12: CARLOS TOLOMEO EL DUENDE | C12: Calle 520 928, Tolosa, Buenos Aires, Argentina | D12: 520 E/ 4 Y 5 N928 | E12: Tolosa 2 | F12: Tolosa | H12: OK | J12: -34.887945 | K12: -57.979531 | L12: Abrir
A13: Zona 04 - Tolosa | B13: CHARUTO GROW SHOP | C13: Calle 8 1027, Tolosa, Buenos Aires, Argentina | D13: 8 N°1027 E/ 53 Y 54 | E13: Tolosa | F13: Tolosa | H13: OK | J13: -34.892718 | K13: -57.981571 | L13: Abrir
A14: Zona 04 - Tolosa | B14: GONZALO NAHUEL FERNANDEZ (ALM LA RAMBLA) | C14: Diagonal 524 156, Tolosa, Buenos Aires, Argentina | D14: DIAG 524 Nº156 E/ 18 Y 19 | E14: Tolosa | F14: Tolosa | H14: OK | J14: -34.905635 | K14: -57.987944 | L14: Abrir
A15: Zona 04 - Tolosa | B15: JIANCHAO WU | C15: Calle 116 846, Tolosa, Buenos Aires, Argentina | D15: 116 N 846 E/ 523 Y 524 | E15: Tolosa | F15: Tolosa | H15: OK | J15: -34.886035 | K15: -57.970462 | L15: Abrir
A16: Zona 04 - Tolosa | B16: JIMENEZ NESTOR | C16: Avenida 19 326, Tolosa, Buenos Aires, Argentina | D16: AV 19 E/ 528 Y 529 Nº 326 | E16: Tolosa | F16: Tolosa | H16: OK | J16: -34.909068 | K16: -57.985299 | L16: Abrir
... A31: Zona 04 - Tolosa | B31: TULIZ MARIO | C31: Calle 526 1700, Tolosa, Buenos Aires, Argentina | D31: 526 N 1700 E/ 11 Y 12 | E31: Tolosa | F31: Tolosa | H31: OK | J31: -34.900188 | K31: -57.980818 | L31: Abrir

Sheet Zona 05 Lateral San Carlos
A1: Zona 05 - Lateral San Carlos | B1: CHRISTIAN
A2: 22 puntos de venta
A4: Zona | B4: Punto de venta | C4: Dirección (mapa) | D4: Dirección original | E4: Barrio | F4: Localidad | G4: Observación | H4: Estado | I4: Zona más cercana (si está fuera) | J4: Lat | K4: Lng | L4: Ver en Maps | M4: Corrección aplicada
A5: Zona 05 - Lateral San Carlos | B5: COMBUSTIBLES IDELPLA S.A | C5: Calle 520 y Calle 31, José Hernández, La Plata, Buenos Aires, Argentina | D5: 520 Y 31 ESTACION DE SERVICIO VOY | E5: J. Hernandez | F5: José Hernández, La Plata | H5: OK | J5: -34.91232 | K5: -58.00684 | L5: Abrir
A6: Zona 05 - Lateral San Carlos | B6: JUAN RAUL | C6: Calle 523 3240, José Hernández, La Plata, Buenos Aires, Argentina | D6: 523 3240 E/ 27 Y 28 | E6: J Hernandez | F6: José Hernández, La Plata | H6: OK | J6: -34.912338 | K6: -58.000856 | L6: Abrir
A7: Zona 05 - Lateral San Carlos | B7: AGUEDA REY ESPARZA | C7: Diagonal 73 2626, La Plata, Buenos Aires, Argentina | D7: DIAG 73 º2626 E/ 41 Y 42 | E7: La Plata 3 | F7: La Plata | H7: OK | J7: -34.922298 | K7: -57.972357 | L7: Abrir
A8: Zona 05 - Lateral San Carlos | B8: ELISA ANDIA VALLEJOS | C8: Calle 22 151, La Plata, Buenos Aires, Argentina | D8: 22 Y 35 Nº 151 | E8: La Plata | F8: La Plata | H8: OK | J8: -34.917366 | K8: -57.980934 | L8: Abrir
A9: Zona 05 - Lateral San Carlos | B9: GASTON SMITH | C9: Calle 33 1309, La Plata, Buenos Aires, Argentina | D9: 33 N1309 E 21/ 22 | E9: La Plata 3 | F9: La Plata | H9: OK | J9: -34.914707 | K9: -57.982433 | L9: Abrir
A10: Zona 05 - Lateral San Carlos | B10: GUILLERMO MORRIS (KIOSCO VERDE TOPLINE) | C10: Diagonal 73 y Calle 42, La Plata, Buenos Aires, Argentina | D10: DIAG 73 ESQ 42 Y 21 | E10: La Plata 3 | F10: La Plata | H10: OK | J10: -34.922183 | K10: -57.971979 | L10: Abrir
A11: Zona 05 - Lateral San Carlos | B11: MARIA SOL AMANTE | C11: Diagonal 73 2792, La Plata, Buenos Aires, Argentina | D11: DIAG 73 Nº2792 ESQ 23 Y 40 | E11: La Plata 3 | F11: La Plata | H11: OK | J11: -34.922487 | K11: -57.975795 | L11: Abrir
A12: Zona 05 - Lateral San Carlos | B12: SILVIO BONATTO | C12: Diagonal 73 2724, La Plata, Buenos Aires, Argentina | D12: DIAG 73 Nº2724 E/ 40 Y 41 | E12: La Plata 3 | F12: La Plata | H12: OK | J12: -34.922449 | K12: -57.974883 | L12: Abrir
A13: Zona 05 - Lateral San Carlos | B13: YANINA DA FONSECA - CATALEIA | C13: Calle 33 1800, La Plata, Buenos Aires, Argentina | D13: 33 ESQ 31 º1800 | E13: La Plata | F13: La Plata | H13: OK | J13: -34.923842 | K13: -57.992186 | L13: Abrir
A14: Zona 05 - Lateral San Carlos | B14: ERIC FRANCO SANDI | C14: Calle 520 4878, Melchor Romero, Buenos Aires, Argentina | D14: 520 E/143 Y 144 Nº4878 | E14: M Romero | F14: Melchor Romero | H14: OK | J14: -34.92541 | K14: -58.020553 | L14: Abrir
A15: Zona 05 - Lateral San Carlos | B15: CHEN TENGHUI COMPRA FÁCIL | C15: Calle 137 183, San Carlos, La Plata, Buenos Aires, Argentina | D15: 137 E/ 35 Y 35BIS º183 | E15: San Carlos | F15: San Carlos, La Plata | H15: OK | J15: -34.93232 | K15: -57.996539 | L15: Abrir
A16: Zona 05 - Lateral San Carlos | B16: DANIEL DIDEK | C16: Avenida 38 1969, San Carlos, La Plata, Buenos Aires, Argentina | D16: AV. 38 N 1969 E/ 134 Y 135 | E16: San Carlos | F16: San Carlos, La Plata | H16: OK | J16: -34.931505 | K16: -57.990664 | L16: Abrir
... A26: Zona 05 - Lateral San Carlos | B26: PABLO UYUNI | C26: Calle 25 632, Tolosa, Buenos Aires, Argentina | D26: 25 E/ 525 Y 526 Nº632 | E26: Tolosa | F26: Tolosa | H26: OK | J26: -34.912064 | K26: -57.994881 | L26: Abrir

Sheet Zona 06 Hipodromo
A1: Zona 06 - Hipodromo | B1: CHRISTIAN
A2: 25 puntos de venta
A4: Zona | B4: Punto de venta | C4: Dirección (mapa) | D4: Dirección original | E4: Barrio | F4: Localidad | G4: Observación | H4: Estado | I4: Zona más cercana (si está fuera) | J4: Lat | K4: Lng | L4: Ver en Maps | M4: Corrección aplicada
A5: Zona 06 - Hipodromo | B5: DIEGO HERRERA | C5: Calle 125 166, Ensenada, Buenos Aires, Argentina | D5: 125 E/ 35 BIS NUM 166 | E5: Ensenada | F5: Ensenada | H5: OK | J5: -34.887038 | K5: -57.947305 | L5: Abrir
A6: Zona 06 - Hipodromo | B6: ESTEBAN- LOS OLIVOS GAS S.A (AXION) | C6: Calle 122 716, Ensenada, Buenos Aires, Argentina | D6: 122 N°716 | E6: Ensenada | F6: Ensenada | H6: OK | J6: -34.898298 | K6: -57.938523 | L6: Abrir
A7: Zona 06 - Hipodromo | B7: GARABANO FERNANDO - KIOSCO UNDER ENSENADA | C7: Calle 122 157, Ensenada, Buenos Aires, Argentina | D7: N157 122 Y 35 | E7: Ensenada | F7: Ensenada | H7: OK | J7: -34.889888 | K7: -57.950648 | L7: Abrir
A8: Zona 06 - Hipodromo | B8: JESSICA REYES CERNA | C8: Calle 38 71, Ensenada, Buenos Aires, Argentina | D8: 38 N°71 E/ 127 Y 128 | E8: Ensenada | F8: Ensenada | H8: OK | J8: -34.891449 | K8: -57.946343 | L8: Abrir
A9: Zona 06 - Hipodromo | B9: RODOLFO MARCELO MARTIN MOLINA (NANCY) | C9: Calle 124 1489, Ensenada, Buenos Aires, Argentina | D9: 124 E/ 5 Y 6 Nº 1489 | E9: Ensenada | F9: Ensenada | H9: OK | J9: -34.900333 | K9: -57.932836 | L9: Abrir
A10: Zona 06 - Hipodromo | B10: VALERIA JALDIN (126 DIQUE) | C10: Calle 126 y Calle 48, Ensenada, Buenos Aires, Argentina | D10: 126 E/ 48 Y 48 BIS | E10: Ensenada | F10: Ensenada | H10: OK | J10: -34.8969 | K10: -57.933653 | L10: Abrir
A11: Zona 06 - Hipodromo | B11: ANTOJOS KIOSCO AMARILLO | C11: Diagonal 80 678, La Plata, Buenos Aires, Argentina | D11: DIAG 80 º678 E/ 1 Y 2 | E11: La Plata | F11: La Plata | H11: OK | J11: -34.90638 | K11: -57.948849 | L11: Abrir
A12: Zona 06 - Hipodromo | B12: CARINA MORA LLANOS | C12: Diagonal 80 710, La Plata, Buenos Aires, Argentina | D12: DIAG 80 ESQ 2 º710 | E12: La Plata | F12: La Plata | H12: OK | J12: -34.907255 | K12: -57.948752 | L12: Abrir
A13: Zona 06 - Hipodromo | B13: DIEGO MIGUEL CERDA (KIOSCO 74 STOP) | C13: Diag74 118, La Plata, Buenos Aires, Argentina | D13: DIAG74 n118 e/BOULEVARD 83 Y 119 | E13: La Plata | F13: La Plata | H13: OK | J13: -34.891558 | K13: -57.956227 | L13: Abrir
A14: Zona 06 - Hipodromo | B14: DISTRI RAICES - COOP. SAN PEDRO | C14: Calle 32 286, La Plata, Buenos Aires, Argentina | D14: 32 E/ 1 Y 115 N286 | E14: La Plata | F14: La Plata | H14: OK | J14: -34.894823 | K14: -57.962316 | L14: Abrir
A15: Zona 06 - Hipodromo | B15: ENRIQUE GUILLERMO JONGEWAARD | C15: Diag.80 254, La Plata, Buenos Aires, Argentina | D15: DIAG.80 N°254 E 117Y118 | F15: La Plata | H15: OK | J15: -34.898861 | K15: -57.949319 | L15: Abrir
A16: Zona 06 - Hipodromo | B16: ESTEFANIA ROJAS | C16: Diagonal 80 465, La Plata, Buenos Aires, Argentina | D16: DIAG 80 Nº 465 E/ 115 Y 116 | E16: La Plata | F16: La Plata | H16: OK | J16: -34.902589 | K16: -57.949475 | L16: Abrir
A17: Zona 06 - Hipodromo | B17: GISELA SOLEDAD LLANOS | C17: Calle 37 182, La Plata, Buenos Aires, Argentina | D17: CALLE 37 N182 E/ 116 Y 117 FRENTE A HOSPITAL ROSSI | E17: La Plata | F17: La Plata | H17: OK | J17: -34.896952 | K17: -57.954609 | L17: Abrir
A18: Zona 06 - Hipodromo | B18: HORACIO STREMEL | C18: Calle 1 599, La Plata, Buenos Aires, Argentina | D18: 1 Y 44 º599 | E18: La Plata | F18: La Plata | H18: OK | J18: -34.904347 | K18: -57.950111 | L18: Abrir | M18: Pin corregido según la grilla de calles de La Plata
A19: Zona 06 - Hipodromo | B19: LLAMAR ANTES - LUCIANO DIANA (KIOSCO PARADA 1) | C19: Avenida 1 631, La Plata, Buenos Aires, Argentina | D19: AV 1 N°631 e/ 44 Y 45 | E19: La Plata | F19: La Plata | H19: OK | J19: -34.905708 | K19: -57.948597 | L19: Abrir
A20: Zona 06 - Hipodromo | B20: MARIANA ESCRICH | C20: Calle 39 y Diagonal 114, La Plata, Buenos Aires, Argentina | D20: 39 Y DIAG 114 | E20: La Plata | F20: La Plata | H20: OK | J20: -34.89564 | K20: -57.948038 | L20: Abrir
A21: Zona 06 - Hipodromo | B21: MARTIN ARREGUI (RELOJES ARREGUI) | C21: Calle 1 575, La Plata, Buenos Aires, Argentina | D21: 1 Nº 575 E/ 43 Y 44 | E21: La Plata | F21: La Plata | H21: OK | J21: -34.903985 | K21: -57.950598 | L21: Abrir | M21: Pin corregido según la grilla de calles de La Plata
A22: Zona 06 - Hipodromo | B22: MAURO GONZALEZ | C22: Calle 2 631, La Plata, Buenos Aires, Argentina | D22: 2 N°631 E/ 44 Y 45 | E22: La Plata | F22: La Plata | H22: OK | J22: -34.906749 | K22: -57.949675 | L22: Abrir | M22: Caía en el solape zonas 5/17: asignado a 17 (Melchor Romero)
A23: Zona 06 - Hipodromo | B23: REAL IMPERIO LA REINA | C23: Avenida 1 604, La Plata, Buenos Aires, Argentina | D23: AV 1 604 ESQ 44 | E23: La Plata | F23: La Plata | H23: OK | J23: -34.905052 | K23: -57.948801 | L23: Abrir
A24: Zona 06 - Hipodromo | B24: ROXANA LUJAN | C24: Calle 38 35, La Plata, Buenos Aires, Argentina | D24: 38 Nº35 E/ 120 Y 121 | E24: La Plata | F24: La Plata | H24: OK | J24: -34.894947 | K24: -57.950653 | L24: Abrir
A25: Zona 06 - Hipodromo | B25: SANZ JAVIER | C25: Calle 36 228, La Plata, Buenos Aires, Argentina | D25: 36 Y DIAGONAL 74 º228 - SHELL | E25: La Plata | F25: La Plata | H25: OK | J25: -34.89701 | K25: -57.956647 | L25: Abrir
A26: Zona 06 - Hipodromo | B26: SARA VANESSA CARBAJAL | C26: Calle 40 87, La Plata, Buenos Aires, Argentina | D26: calle 40 E 118 Y 119 n87 | E26: La Plata | F26: La Plata | H26: OK | J26: -34.894967 | K26: -57.945959 | L26: Abrir
A27: Zona 06 - Hipodromo | B27: SILVIA PORCO | C27: Calle 42 308, La Plata, Buenos Aires, Argentina | D27: 42 Nº308 E/ 1 Y 2 | E27: La Plata | F27: La Plata | H27: OK | J27: -34.903708 | K27: -57.951488 | L27: Abrir
A28: Zona 06 - Hipodromo | B28: SOLEDAD CISNEROS | C28: Calle 2 y Calle 45, La Plata, Buenos Aires, Argentina | D28: CALLE 2 E/ 45 Y 46 | E28: La Plata | F28: La Plata | H28: OK | J28: -34.906071 | K28: -57.949848 | L28: Abrir
A29: Zona 06 - Hipodromo | B29: VIVIANA ERRAMOUSPE | C29: Calle 40 92, La Plata, Buenos Aires, Argentina | D29: 40 º92 DIAG 80 | E29: La Plata | F29: La Plata | H29: OK | J29: -34.894742 | K29: -57.946328 | L29: Abrir

Sheet Zona 07 Lateral Norte
A1: Zona 07 - Lateral Norte | B1: CHRISTIAN
A2: 32 puntos de venta
A4: Zona | B4: Punto de venta | C4: Dirección (mapa) | D4: Dirección original | E4: Barrio | F4: Localidad | G4: Observación | H4: Estado | I4: Zona más cercana (si está fuera) | J4: Lat | K4: Lng | L4: Ver en Maps | M4: Corrección aplicada
A5: Zona 07 - Lateral Norte | B5: ADRIANA LORENA LEDESMA LO DE ADRY | C5: Calle 31 2332, José Hernández, La Plata, Buenos Aires, Argentina | D5: 31 E/ 508 Y 509 º2332 | E5: José Hernández | F5: José Hernández, La Plata | H5: OK | J5: -34.917095 | K5: -57.969263 | L5: Abrir
A6: Zona 07 - Lateral Norte | B6: MATIAS RAMOS | C6: Calle 133 2281, José Hernández, La Plata, Buenos Aires, Argentina | D6: 133 º2281 E/ 509 Y 510 | E6: José Hernández | F6: José Hernández, La Plata | H6: OK | J6: -34.917095 | K6: -57.969263 | L6: Abrir
A7: Zona 07 - Lateral Norte | B7: BONTEMPO RAMIRO | C7: Plaza Paso 51, La Plata, Buenos Aires, Argentina | D7: PLAZA PASO N 51 ESQ. 13 Y 44 | E7: La Plata | F7: La Plata | H7: OK | J7: -34.916988 | K7: -57.961736 | L7: Abrir
A8: Zona 07 - Lateral Norte | B8: DAMIAN ZLATAR - KIOSCO RUMBO | C8: Calle 12 649, La Plata, Buenos Aires, Argentina | D8: CALLE 12 N649 ESQ 45 | E8: La Plata | F8: La Plata | H8: OK | J8: -34.916202 | K8: -57.959436 | L8: Abrir
A9: Zona 07 - Lateral Norte | B9: FEDERICO KOLENDER | C9: Calle 12 805, La Plata, Buenos Aires, Argentina | D9: 12 805 E/ 48 Y 49 | E9: La Plata | F9: La Plata | H9: OK | J9: -34.91861 | K9: -57.956301 | L9: Abrir
A10: Zona 07 - Lateral Norte | B10: FIAMMA MAZZEO | C10: Calle 46 y Calle 11, La Plata, Buenos Aires, Argentina | D10: 46 Y 11 | E10: La Plata | F10: La Plata | H10: OK | J10: -34.916073 | K10: -57.957185 | L10: Abrir
A11: Zona 07 - Lateral Norte | B11: FLOR LIMA | C11: Calle 14 387, La Plata, Buenos Aires, Argentina | D11: CALLE 14 N 387 E 39 Y 40 | E11: La Plata | F11: La Plata | H11: OK | J11: -34.913728 | K11: -57.967472 | L11: Abrir
A12: Zona 07 - Lateral Norte | B12: GARABANO FERNANDO - KIOSCO UNDER | C12: Calle 12 510, La Plata, Buenos Aires, Argentina | D12: 12 510 e/ 42 Y 43 | E12: La Plata | F12: La Plata | H12: OK | J12: -34.914175 | K12: -57.961713 | L12: Abrir
A13: Zona 07 - Lateral Norte | B13: GENEIRO LILIANA | C13: Calle 46 856, La Plata, Buenos Aires, Argentina | D13: 46 856 E/ 12 Y 13 | E13: La Plata | F13: La Plata | H13: OK | J13: -34.917338 | K13: -57.958137 | L13: Abrir
A14: Zona 07 - Lateral Norte | B14: GRISELLA VILLIVA | C14: Calle 42 1147, La Plata, Buenos Aires, Argentina | D14: 42 º1147 ESQ 18 | E14: La Plata 3 | F14: La Plata | H14: OK | J14: -34.919103 | K14: -57.968863 | L14: Abrir
A15: Zona 07 - Lateral Norte | B15: HORACIO TILBE (JUAN) LP | C15: Calle 44 799, La Plata, Buenos Aires, Argentina | D15: 44 N 799 Y 11 | E15: La Plata | F15: La Plata | H15: OK | J15: -34.913887 | K15: -57.960192 | L15: Abrir | M15: Pin corregido según la grilla de calles de La Plata
A16: Zona 07 - Lateral Norte | B16: JUAN PABLO BISOGNI | C16: Calle 15 1004, La Plata, Buenos Aires, Argentina | D16: CALLE 15 1004 ESQ 44 | E16: La Plata | F16: La Plata | H16: OK | J16: -34.917703 | K16: -57.964224 | L16: Abrir | M16: Pin corregido según la grilla de calles de La Plata
A17: Zona 07 - Lateral Norte | B17: KAPRI ALONZO LUIS PLAZA N°41 | C17: Plaza Paso 41, La Plata, Buenos Aires, Argentina | D17: PLAZA PASO N 41 | E17: La Plata | F17: La Plata | H17: OK | J17: -34.915727 | K17: -57.961885 | L17: Abrir
A18: Zona 07 - Lateral Norte | B18: LIN JIANLIN | C18: Calle 15 380, La Plata, Buenos Aires, Argentina | D18: 15 E/ 39 Y 40 Nº380 | E18: La Plata 3 | F18: La Plata | H18: OK | J18: -34.914292 | K18: -57.968296 | L18: Abrir
A19: Zona 07 - Lateral Norte | B19: LIU XIUYAN | C19: Calle 13 643, La Plata, Buenos Aires, Argentina | D19: 13 Nº 643 E/ 44 Y 45 | E19: La Plata | F19: La Plata | H19: OK | J19: -34.917251 | K19: -57.960466 | L19: Abrir
A20: Zona 07 - Lateral Norte | B20: LUCAS NUÑEZ | C20: Calle 49 874, La Plata, Buenos Aires, Argentina | D20: 49 E/ 12 Y 13 º874 | E20: La Plata | F20: La Plata | H20: OK | J20: -34.919503 | K20: -57.95585 | L20: Abrir
A21: Zona 07 - Lateral Norte | B21: MARILIN ALEJANDRA BISIO | C21: Calle 13 21, La Plata, Buenos Aires, Argentina | D21: 13 ENTRE 32 Y 33 Nº 21 | E21: La Plata 3 | F21: La Plata | H21: OK | J21: -34.906691 | K21: -57.974623 | L21: Abrir | M21: Caía en el solape zonas 5/17: asignado a 17 (Melchor Romero)
A22: Zona 07 - Lateral Norte | B22: MAURICIO EZEQUIEL GONZÁLEZ | C22: Calle 47 846, La Plata, Buenos Aires, Argentina | D22: 47 846 E/ 11 Y 12 | E22: La Plata | F22: La Plata | H22: OK | J22: -34.917619 | K22: -57.957013 | L22: Abrir
A23: Zona 07 - Lateral Norte | B23: MAXIMILIANO DALLERA | C23: Calle 38 1053, La Plata, Buenos Aires, Argentina | D23: 38 n1053 ESQ 16 | E23: La Plata 3 | F23: La Plata | H23: OK | J23: -34.914046 | K23: -57.971561 | L23: Abrir
A24: Zona 07 - Lateral Norte | B24: MIA PECEROS | C24: Calle 13 723, La Plata, Buenos Aires, Argentina | D24: 13 N723 E46 Y 47 | E24: La Plata Centro | F24: La Plata | H24: OK | J24: -34.918471 | K24: -57.958895 | L24: Abrir
A25: Zona 07 - Lateral Norte | B25: NOTO JAVIER ALEJANDRO | C25: Calle 18 221, La Plata, Buenos Aires, Argentina | D25: 18 N 221 E 36 Y 37 | E25: La Plata 3 | F25: La Plata | H25: OK | J25: -34.914557 | K25: -57.975396 | L25: Abrir
A26: Zona 07 - Lateral Norte | B26: RAUL HERNÁN ANDIA VALLEJOS | C26: Calle 41 y Calle 16, La Plata, Buenos Aires, Argentina | D26: 41 ESQ 16 - VERDULERÍA | E26: La Plata 3 | F26: La Plata | H26: OK | J26: -34.916609 | K26: -57.967928 | L26: Abrir
A27: Zona 07 - Lateral Norte | B27: SANTIAGO ARIAS LOS BÚHOS | C27: Calle 19 13, La Plata, Buenos Aires, Argentina | D27: 19 E/ 32 Y 33 Nº 13 | E27: La Plata | F27: La Plata | H27: OK | J27: -34.913209 | K27: -57.979466 | L27: Abrir | M27: Pin corregido según la grilla de calles de La Plata
A28: Zona 07 - Lateral Norte | B28: SCHNEIDER DANIEL | C28: Calle 19 149, La Plata, Buenos Aires, Argentina | D28: 19 Y 35 N 149 | E28: La Plata | F28: La Plata | H28: OK | J28: -34.915016 | K28: -57.977029 | L28: Abrir | M28: Pin corregido según la grilla de calles de La Plata
A29: Zona 07 - Lateral Norte | B29: SEBASTIAN DEL DAGO | C29: Calle 13 701, La Plata, Buenos Aires, Argentina | D29: 13 701 E/ 46 Y 47 | E29: La Plata Centro | F29: La Plata | H29: OK | J29: -34.918207 | K29: -57.959276 | L29: Abrir
A30: Zona 07 - Lateral Norte | B30: SUPER SEBASTIAN | C30: Calle 15 y Calle 36, La Plata, Buenos Aires, Argentina | D30: 15 Y 36 | E30: La Plata 3 | F30: La Plata | H30: OK | J30: -34.911568 | K30: -57.972592 | L30: Abrir
A31: Zona 07 - Lateral Norte | B31: SUPERMERCADO LA LINDA | C31: Calle 47 836, La Plata, Buenos Aires, Argentina | D31: 47 N836 E/ 11 Y 12 | E31: La Plata | F31: La Plata | H31: OK | J31: -34.917577 | K31: -57.956582 | L31: Abrir
A32: Zona 07 - Lateral Norte | B32: TERESA RAMONA GALARZA | C32: Calle 19 436, La Plata, Buenos Aires, Argentina | D32: 19 E/ 40 Y 41 Nº436 | E32: La Plata 3 | F32: La Plata | H32: OK | J32: -34.91899 | K32: -57.971668 | L32: Abrir | M32: Pin corregido según la grilla de calles de La Plata
A33: Zona 07 - Lateral Norte | B33: TORRES MARTA ELENA | C33: Calle 35 1053, La Plata, Buenos Aires, Argentina | D33: 35 1053 ESQ. 16 | E33: La Plata 3 | F33: La Plata | H33: OK | J33: -34.911506 | K33: -57.974912 | L33: Abrir
A34: Zona 07 - Lateral Norte | B34: VICTORIA GOICOECHEA - KIOSCO PEPO | C34: Calle 44 833, La Plata, Buenos Aires, Argentina | D34: 44 Nº 833 E/ 11 Y 12 | E34: La Plata | F34: La Plata | H34: OK | J34: -34.914364 | K34: -57.960696 | L34: Abrir | M34: Pin corregido según la grilla de calles de La Plata
A35: Zona 07 - Lateral Norte | B35: YE JIAFENG | C35: Calle 14 195, La Plata, Buenos Aires, Argentina | D35: 14 Nº 195 E/ 35 Y 36 | E35: La Plata 3 | F35: La Plata | H35: OK | J35: -34.910466 | K35: -57.971908 | L35: Abrir
A36: Zona 07 - Lateral Norte | B36: CHI GUAQUAN (SUPER EL DRAGON) | C36: Calle 19 186, Tolosa, Buenos Aires, Argentina | D36: 19 E/35 Y 36 Nº186 | E36: Tolosa | F36: Tolosa | H36: OK | J36: -34.915377 | K36: -57.976542 | L36: Abrir | M36: Pin corregido según la grilla de calles de La Plata

Sheet Zona 08 Lateral Centro Nor
A1: Zona 08 - Lateral Centro Norte | B1: PABLO
A2: 25 puntos de venta
A4: Zona | B4: Punto de venta | C4: Dirección (mapa) | D4: Dirección original | E4: Barrio | F4: Localidad | G4: Observación | H4: Estado | I4: Zona más cercana (si está fuera) | J4: Lat | K4: Lng | L4: Ver en Maps | M4: Corrección aplicada
A5: Zona 08 - Lateral Centro Norte | B5: BALDASSO NOELIA (EX FLAVIA GISELE MARINO) | C5: Calle 6 96, La Plata, Buenos Aires, Argentina | D5: 6 Nº96 E/ 33 Y 34 | E5: La Plata | F5: La Plata | H5: OK | J5: -34.901045 | K5: -57.965639 | L5: Abrir
A6: Zona 08 - Lateral Centro Norte | B6: BECERRA ZAFRA 47 Y 5 ALEIVIN | C6: Calle 47 503, La Plata, Buenos Aires, Argentina | D6: 47 ESQUINA 5 N 503 | E6: La Plata | F6: La Plata | H6: OK | J6: -34.91115 | K6: -57.950212 | L6: Abrir
A7: Zona 08 - Lateral Centro Norte | B7: BITURON BLANCA CRISTINA (KATERINA) | C7: Pza Italia 10, La Plata, Buenos Aires, Argentina | D7: PZA ITALIA N°10 E/ 44 Y DIAG 74 | E7: La Plata | F7: La Plata | H7: OK | J7: -34.909857 | K7: -57.954776 | L7: Abrir
A8: Zona 08 - Lateral Centro Norte | B8: CAMILA CAMAÑO | C8: Diagonal 80 1032, La Plata, Buenos Aires, Argentina | D8: DIAGONAL 80 E/ 49 Y 50 º1032 | E8: La Plata | F8: La Plata | H8: OK | J8: -34.912971 | K8: -57.948422 | L8: Abrir
A9: Zona 08 - Lateral Centro Norte | B9: CARLA - FULL 365 (FRENTE TERMINAL) | C9: Calle 42 440, La Plata, Buenos Aires, Argentina | D9: 42 440 E 3 Y 4 | E9: La Plata | F9: La Plata | H9: OK | J9: -34.90615 | K9: -57.954072 | L9: Abrir
A10: Zona 08 - Lateral Centro Norte | B10: CULTURA DE LONGSHAN | C10: Calle 3 325, La Plata, Buenos Aires, Argentina | D10: 3 E/ 38 Y 39 Nº325 | E10: La Plata | F10: La Plata | H10: OK | J10: -34.902424 | K10: -57.957519 | L10: Abrir
A11: Zona 08 - Lateral Centro Norte | B11: DANIEL SOLARI | C11: Diagonal 74 1150, La Plata, Buenos Aires, Argentina | D11: DIAG 74 E/ 6 Y PZA ITALIA N°1150 | E11: La Plata | F11: La Plata | H11: OK | J11: -34.909694 | K11: -57.955126 | L11: Abrir
A12: Zona 08 - Lateral Centro Norte | B12: DRUGSTORE 6Y43 - MATIAS PASCUAL | C12: Calle 6 y Calle 43, La Plata, Buenos Aires, Argentina | D12: ESQ 6 Y 43 | E12: La Plata | F12: La Plata | H12: OK | J12: -34.908394 | K12: -57.956126 | L12: Abrir | M12: Pin corregido según la grilla de calles de La Plata
A13: Zona 08 - Lateral Centro Norte | B13: FACHAL SANTIAGO | C13: Calle 48 516, La Plata, Buenos Aires, Argentina | D13: 48 E/ 5 Y 6 N 516 | E13: La Plata | F13: La Plata | H13: OK | J13: -34.912265 | K13: -57.949317 | L13: Abrir
A14: Zona 08 - Lateral Centro Norte | B14: GABRIEL RAMIREZ - MAXIKIOSCO 46 | C14: Calle 3 407, La Plata, Buenos Aires, Argentina | D14: 3 ESQ 46 N 407 JUSTO ESQUINA | E14: La Plata | F14: La Plata | H14: OK | J14: -34.9077 | K14: -57.950177 | L14: Abrir | M14: Pin corregido según la grilla de calles de La Plata
A15: Zona 08 - Lateral Centro Norte | B15: JUAN CARLOS CAMPOS | C15: Calle 50 461, La Plata, Buenos Aires, Argentina | D15: 50 461 E/ 4 Y 5 | E15: La Plata | F15: La Plata | H15: OK | J15: -34.912131 | K15: -57.947024 | L15: Abrir
A16: Zona 08 - Lateral Centro Norte | B16: LEONARDO D'ALOISIO MAXIKIOSCO POP | C16: Calle 43 548, La Plata, Buenos Aires, Argentina | D16: 43 º548 ESQ 6 Y DIAG 74 | E16: La Plata | F16: La Plata | H16: OK | J16: -34.908877 | K16: -57.955162 | L16: Abrir
A17: Zona 08 - Lateral Centro Norte | B17: LIU DONG | C17: Calle 4 868, La Plata, Buenos Aires, Argentina | D17: 4 N°868 E/ 49 Y 50 | E17: La Plata | F17: La Plata | H17: OK | J17: -34.911635 | K17: -57.947044 | L17: Abrir
A18: Zona 08 - Lateral Centro Norte | B18: LUIS EZEQUIEL LUCE | C18: Calle 45 549, La Plata, Buenos Aires, Argentina | D18: 45 E/ 5 Y 6 º549 | E18: La Plata | F18: La Plata | H18: OK | J18: -34.910388 | K18: -57.952976 | L18: Abrir
A19: Zona 08 - Lateral Centro Norte | B19: MANUEL DIAZ | C19: Calle 47 545, La Plata, Buenos Aires, Argentina | D19: 47 545 E/ 5 Y 6 | E19: Centro La Plata | F19: La Plata | H19: OK | J19: -34.911946 | K19: -57.951 | L19: Abrir
A20: Zona 08 - Lateral Centro Norte | B20: MARCELA Y HUGO | C20: Calle 47 545, La Plata, Buenos Aires, Argentina | D20: CALLE 47 Nº 545 CASI ESQ. 6 | E20: La Plata | F20: La Plata | H20: OK | J20: -34.911946 | K20: -57.951 | L20: Abrir
A21: Zona 08 - Lateral Centro Norte | B21: NEYRA JOAQUIN 49 | C21: Calle 49 519, La Plata, Buenos Aires, Argentina | D21: 49 N 519 Y DIAG. 80 | E21: La Plata | F21: La Plata | H21: OK | J21: -34.912738 | K21: -57.948719 | L21: Abrir
A22: Zona 08 - Lateral Centro Norte | B22: NEYRA JOAQUIN DIAG 80 | C22: Diagonal 80 1087, La Plata, Buenos Aires, Argentina | D22: DIAGONAL 80 N 1087 E/ 5 Y 6 | E22: La Plata | F22: La Plata | H22: OK | J22: -34.9135 | K22: -57.948762 | L22: Abrir
A23: Zona 08 - Lateral Centro Norte | B23: NO STOP 5 Y 42 JOAQUÍN CUERVO | C23: Calle 5 500, La Plata, Buenos Aires, Argentina | D23: 5 º500 ESQ 42 | E23: La Plata | F23: La Plata | H23: OK | J23: -34.907022 | K23: -57.955534 | L23: Abrir
A24: Zona 08 - Lateral Centro Norte | B24: NO STOP 7 N 566 JULIAN | C24: Plaza Italia 566, La Plata, Buenos Aires, Argentina | D24: PLAZA ITALIA Y 7 N 566 | E24: La Plata | F24: La Plata | H24: OK | J24: -34.911001 | K24: -57.954434 | L24: Abrir
A25: Zona 08 - Lateral Centro Norte | B25: PABLO CAVALLO | C25: Calle 48 523, La Plata, Buenos Aires, Argentina | D25: 48 Nº523 E/ 5 Y 6 | E25: La Plata | F25: La Plata | H25: OK | J25: -34.912129 | K25: -57.949845 | L25: Abrir
A26: Zona 08 - Lateral Centro Norte | B26: PAOLA MANSINO | C26: Calle 7 542, La Plata, Buenos Aires, Argentina | D26: 7 Nº 542 E/ 42 Y 43 | E26: La Plata | F26: La Plata | H26: OK | J26: -34.909472 | K26: -57.956539 | L26: Abrir
... A28: Zona 08 - Lateral Centro Norte | B28: VALLEJOS CARINA | C28: Calle 3 200, La Plata, Buenos Aires, Argentina | D28: 3 Y 36 N 200 | E28: La Plata | F28: La Plata | H28: OK | J28: -34.900159 | K28: -57.960117 | L28: Abrir
A29: Zona 08 - Lateral Centro Norte | B29: YANI YUSSO | C29: Calle 51 355, La Plata, Buenos Aires, Argentina | D29: 51 º355 E/ 2 Y 3 | E29: La Plata | F29: La Plata | H29: OK | J29: -34.910836 | K29: -57.9448 | L29: Abrir | M29: Pin corregido según la grilla de calles de La Plata

Sheet Zona 9 Noroeste
A1: Zona 10 - Noroeste | B1: PABLO
A2: 23 puntos de venta
A4: Zona | B4: Punto de venta | C4: Dirección (mapa) | D4: Dirección original | E4: Barrio | F4: Localidad | G4: Observación | H4: Estado | I4: Zona más cercana (si está fuera) | J4: Lat | K4: Lng | L4: Ver en Maps | M4: Corrección aplicada
A5: Zona 10 - Noroeste | B5: ASTROGROW (JOAQUIN) | C5: Avenida 19 996, La Plata, Buenos Aires, Argentina | D5: AV 19 E/ 51 Y 53 º996 | E5: La Plata 3 | F5: La Plata | H5: OK | J5: -34.92721 | K5: -57.960073 | L5: Abrir
A6: Zona 10 - Noroeste | B6: JUAN (EX ROMINA GARRAFA KIOSCO) | C6: Calle 25 y Calle 44, La Plata, Buenos Aires, Argentina | D6: 25 Y 44 | E6: La Plata | F6: La Plata | H6: OK | J6: -34.927243 | K6: -57.974305 | L6: Abrir | M6: Pin corregido según la grilla de calles de La Plata
A7: Zona 10 - Noroeste | B7: KIOSCO PARADA ZERO (RUBEN COELHO) | C7: Calle 20 898, La Plata, Buenos Aires, Argentina | D7: 20 ESQ 50 º898 | E7: La Plata 3 | F7: La Plata | H7: OK | J7: -34.926829 | K7: -57.963081 | L7: Abrir
A8: Zona 10 - Noroeste | B8: LIN HANGWEI | C8: Calle 46 1376, La Plata, Buenos Aires, Argentina | D8: 46 E/ 22 Y 23 Nº1376 | E8: La Plata | F8: La Plata | H8: OK | J8: -34.927002 | K8: -57.968845 | L8: Abrir
A9: Zona 10 - Noroeste | B9: LIN HANGWEI (SUPER EL DRAGON) | C9: Calle 46 1376, La Plata, Buenos Aires, Argentina | D9: 46 E/ 22 Y 23 N°1376 | E9: La Plata 3 | F9: La Plata | H9: OK | J9: -34.927002 | K9: -57.968845 | L9: Abrir
A10: Zona 10 - Noroeste | B10: LIN XINYI | C10: Calle 49 1510, La Plata, Buenos Aires, Argentina | D10: 49 E/ 25 Y 26 Nº 1510 | E10: La Plata 3 | F10: La Plata | H10: OK | J10: -34.931494 | K10: -57.969088 | L10: Abrir
A11: Zona 10 - Noroeste | B11: LIN XIUMEI | C11: Calle 54 1332, La Plata, Buenos Aires, Argentina | D11: 54 º1332 E/ 21 Y 22 | E11: La Plata 3 | F11: La Plata | H11: OK | J11: -34.930481 | K11: -57.961969 | L11: Abrir
A12: Zona 10 - Noroeste | B12: LORENA MARTINEZ | C12: Calle 49 1082, La Plata, Buenos Aires, Argentina | D12: 49 E 16 Y 17 N°1082 | F12: La Plata | H12: OK | J12: -34.923472 | K12: -57.960207 | L12: Abrir
A13: Zona 10 - Noroeste | B13: MARIELA NAQUED - NEIKY MARKET | C13: Calle 25 y Calle 54, La Plata, Buenos Aires, Argentina | D13: 25 Y 54 | E13: La Plata 3 | F13: La Plata | H13: OK | J13: -34.933635 | K13: -57.965615 | L13: Abrir
A14: Zona 10 - Noroeste | B14: MERIDA FERNANDO JOSE | C14: Calle 51 1147, La Plata, Buenos Aires, Argentina | D14: 51 Y 18 N 1147 | E14: La Plata 3 | F14: La Plata | H14: OK | J14: -34.925541 | K14: -57.960332 | L14: Abrir
A15: Zona 10 - Noroeste | B15: NAHUEL DE LEO AUTOSERVICIO AMICCI | C15: Calle 48 1267, La Plata, Buenos Aires, Argentina | D15: 48 º1267 E/ 20 Y 21 | E15: La Plata | F15: La Plata | H15: OK | J15: -34.926177 | K15: -57.965115 | L15: Abrir
A16: Zona 10 - Noroeste | B16: NICOLAS FEDERICO DEL CORAZON DE JESUS ESCUDIER | C16: Diagonal 73 2015, La Plata, Buenos Aires, Argentina | D16: DIAG 73 º 2015 ESQ 48 | E16: La Plata | F16: La Plata | H16: OK | J16: -34.921451 | K16: -57.959595 | L16: Abrir
A17: Zona 10 - Noroeste | B17: NICOLAS VALLEJOS (EX SUSANA VERDULERÍA) | C17: Calle 19 y Calle 56, La Plata, Buenos Aires, Argentina | D17: 19 Y 56 | E17: La Plata 3 | F17: La Plata | H17: OK | J17: -34.92915 | K17: -57.95818 | L17: Abrir
A18: Zona 10 - Noroeste | B18: PABLO COSTANTINO - DE TODO UN POCO | C18: Diagonal 73 2089, La Plata, Buenos Aires, Argentina | D18: DIAG. 73 Nº 2089 ESQ. 16 | E18: La Plata 3 | F18: La Plata | H18: OK | J18: -34.921539 | K18: -57.961105 | L18: Abrir
A19: Zona 10 - Noroeste | B19: WALTER DANIEL INAMA | C19: Calle 56 1674, La Plata, Buenos Aires, Argentina | D19: 56 N°1674 E/ 28 Y 29 | E19: La Plata 3 | F19: La Plata | H19: OK | J19: -34.938111 | K19: -57.967546 | L19: Abrir
A20: Zona 10 - Noroeste | B20: WALTER HUGO TOBARES | C20: Calle 46 1386, La Plata, Buenos Aires, Argentina | D20: 46 º1386 E/ 22 Y 23 | E20: La Plata 3 | F20: La Plata | H20: OK | J20: -34.927178 | K20: -57.96911 | L20: Abrir
A21: Zona 10 - Noroeste | B21: YRIS CARDOZO | C21: Calle 48 1004, La Plata, Buenos Aires, Argentina | D21: 48 E/ 15 Y DIAG 73 º1004 | E21: La Plata 3 | F21: La Plata | H21: OK | J21: -34.921383 | K21: -57.959502 | L21: Abrir
A22: Zona 10 - Noroeste | B22: ZHANG DONG | C22: Calle 17 779, La Plata, Buenos Aires, Argentina | D22: 17 Nº779 E/ 47 Y 48 | E22: La Plata/2 | F22: La Plata | H22: OK | J22: -34.922846 | K22: -57.961905 | L22: Abrir
A23: Zona 10 - Noroeste | B23: ZHENG AIFENG | C23: Calle 28 1297, La Plata, Buenos Aires, Argentina | D23: 28 Y 59 N 1297 | E23: La Plata 3 | F23: La Plata | H23: OK | J23: -34.939717 | K23: -57.964656 | L23: Abrir
A24: Zona 10 - Noroeste | B24: KIOSCO EL DESPACHITO ARIEL | C24: Calle 47 y Calle 28, San Carlos, La Plata, Buenos Aires, Argentina | D24: 47 Y 28 ESQUINA | E24: San Carlos | F24: San Carlos, La Plata | H24: OK | J24: -34.93024 | K24: -57.97689 | L24: Abrir
A25: Zona 10 - Noroeste | B25: VANINA AUTOSERVICIO (AGUS Y TOMI) | C25: Avenida 31 478, San Carlos, La Plata, Buenos Aires, Argentina | D25: AV 31 E/ 527 Y 528 Nº478 | E25: San Carlos | F25: San Carlos, La Plata | H25: OK | J25: -34.930952 | K25: -57.982529 | L25: Abrir
A26: Zona 10 - Noroeste | B26: GUSTAVO PASCUAL (POLIRRUBRO COLOR AMARILLO) | C26: C. 22 y Calle 44, Tolosa, Buenos Aires, Argentina | D26: C. 22 Y 44 602 (JUSTO EN LA ESQUINA) | E26: Tolosa | F26: Tolosa | H26: OK | J26: -34.924381 | K26: -57.971281 | L26: Abrir | M26: Pin corregido según la grilla de calles de La Plata
A27: Zona 10 - Noroeste | B27: KIOSCO LA PLAZA (ZURITA) | C27: Plaza Azcuenaga 11, Tolosa, Buenos Aires, Argentina | D27: PLAZA AZCUENAGA Nº11 E 44 Y DIAG 76 | E27: Tolosa | F27: Tolosa | H27: OK | J27: -34.921954 | K27: -57.967559 | L27: Abrir

Sheet Zona 10 Centro
A1: Zona 11 - Centro | B1: CHRISTIAN
A2: 30 puntos de venta
A4: Zona | B4: Punto de venta | C4: Dirección (mapa) | D4: Dirección original | E4: Barrio | F4: Localidad | G4: Observación | H4: Estado | I4: Zona más cercana (si está fuera) | J4: Lat | K4: Lng | L4: Ver en Maps | M4: Corrección aplicada
A5: Zona 11 - Centro | B5: 24.7 - MARIA DEL CARMEN FERNANDEZ | C5: Calle 8 950, La Plata, Buenos Aires, Argentina | D5: CALLE 8 N 950 ESQ. 51 | E5: La Plata | F5: La Plata | H5: OK | J5: -34.91612 | K5: -57.950178 | L5: Abrir
A6: Zona 11 - Centro | B6: ALVARADO PAULA | C6: Calle 7 381, La Plata, Buenos Aires, Argentina | D6: 7 N 381 E/ 39 Y 40 | E6: La Plata | F6: La Plata | H6: OK | J6: -34.907258 | K6: -57.960384 | L6: Abrir
A7: Zona 11 - Centro | B7: ANDRÉS EZEQUIEL NUÑEZ KIOSCO ASTRO | C7: Calle 10 860, La Plata, Buenos Aires, Argentina | D7: 10 º860 E/ 49 Y 50 | E7: La Plata | F7: La Plata | H7: OK | J7: -34.917161 | K7: -57.953274 | L7: Abrir
A8: Zona 11 - Centro | B8: AXEL BARZABAL | C8: Calle 48 679, La Plata, Buenos Aires, Argentina | D8: 48 º679 E/ 8 Y 9 | E8: La Plata | F8: La Plata | H8: OK | J8: -34.915234 | K8: -57.95302 | L8: Abrir
A9: Zona 11 - Centro | B9: BAUTISTA MASI | C9: Calle 10 367, La Plata, Buenos Aires, Argentina | D9: CALLE 10 N367 E 39 Y 40 | E9: La Plata | F9: La Plata | H9: OK | J9: -34.909703 | K9: -57.963709 | L9: Abrir
A10: Zona 11 - Centro | B10: BRITEZ CARMELO | C10: Calle 12 y Calle 34, La Plata, Buenos Aires, Argentina | D10: 12 Y 34 | E10: La Plata | F10: La Plata | H10: OK | J10: -34.906936 | K10: -57.971765 | L10: Abrir
A11: Zona 11 - Centro | B11: CARLA REYNAFE - KIOSCO | C11: Avenida 44 665, La Plata, Buenos Aires, Argentina | D11: AV. 44 Nº 665 E/ 8 Y 9 | E11: La Plata Centro | F11: La Plata | H11: OK | J11: -34.911713 | K11: -57.956923 | L11: Abrir
A12: Zona 11 - Centro | B12: CHIAFFITELLI BRUNO FEDERICO | C12: Calle 8 564, La Plata, Buenos Aires, Argentina | D12: 8 Y DIAGONAL 77 N 564 | E12: La Plata | F12: La Plata | H12: OK | J12: -34.91087 | K12: -57.957165 | L12: Abrir
A13: Zona 11 - Centro | B13: CLAUDIA - 24.7 COLAVECCHIA | C13: Calle 50 636, La Plata, Buenos Aires, Argentina | D13: 50 N636 E/ 7 Y 8 | E13: La Plata | F13: La Plata | H13: OK | J13: -34.915599 | K13: -57.950432 | L13: Abrir
A14: Zona 11 - Centro | B14: DAVID VARGAS | C14: Calle 10 608, La Plata, Buenos Aires, Argentina | D14: 10 e/ 44 Y 45 º608 | E14: La Plata | F14: La Plata | H14: OK | J14: -34.913578 | K14: -57.958076 | L14: Abrir
A15: Zona 11 - Centro | B15: DISTRIBUIDORA 33 | C15: Calle 34 372, La Plata, Buenos Aires, Argentina | D15: 34 N 372 E/ 9 Y 10 | E15: La Plata | F15: La Plata | H15: OK | J15: -34.90523 | K15: -57.968427 | L15: Abrir | M15: Pin corregido según la grilla de calles de La Plata
A16: Zona 11 - Centro | B16: FABIANA - 24.7 MARIA FERNANDEZ | C16: Calle 51 601, La Plata, Buenos Aires, Argentina | D16: 51 N601 ESQ. 7 | E16: La Plata | F16: La Plata | H16: OK | J16: -34.915442 | K16: -57.949047 | L16: Abrir
A17: Zona 11 - Centro | B17: FERNANDO GABRIEL DULIO | C17: Calle 11 351, La Plata, Buenos Aires, Argentina | D17: 11 ESQ 39 º351 | E17: La Plata | F17: La Plata | H17: OK | J17: -34.910272 | K17: -57.96512 | L17: Abrir
A18: Zona 11 - Centro | B18: GIMENEZ FABIAN | C18: Calle 51 795, La Plata, Buenos Aires, Argentina | D18: 51 N 795 E/ 10 Y 11 | E18: La Plata | F18: La Plata | H18: OK | J18: -34.918802 | K18: -57.953276 | L18: Abrir
A19: Zona 11 - Centro | B19: HERNAN BALLERINI CALLE 50 | C19: Calle 50 716, La Plata, Buenos Aires, Argentina | D19: 50 E/ 9 Y 10 N 716 | E19: La Plata | F19: La Plata | H19: OK | J19: -34.917145 | K19: -57.951916 | L19: Abrir
A20: Zona 11 - Centro | B20: IVAN PRESTES - FULL 365 KIOSCO ROJO | C20: Avenida 7 701, La Plata, Buenos Aires, Argentina | D20: AV 7 N 701 ESQ. 46 | E20: La Plata | F20: La Plata | H20: OK | J20: -34.912415 | K20: -57.953051 | L20: Abrir
A21: Zona 11 - Centro | B21: KAPRIDRUGSTORE 749 - LUIS ALONSO | C21: Calle 10 y Calle 51, La Plata, Buenos Aires, Argentina | D21: ESQ. 10 Y 51 | E21: La Plata | F21: La Plata | H21: OK | J21: -34.918184 | K21: -57.952114 | L21: Abrir
